Workbook

Sheet 1ST ORDER
B1: 1ST ORDER | F1: SILVER COMPOSITE TEXTILE MILLS LTD. (UNIT-01)
E2: 1ST ORDER CUTTING & INPUT REPORT | L2: 46190
B3: Buyer | C3: Style | D3: P.O No. | E3: Color | F3: Description | G3: XS | H3: S | I3: M | J3: L | K3: XL | L3: Total | M3: REMARKS
B4: GREENSOURCE | C4: SHACKET-G074 | D4: 14220+22 | E4: WILD ONE | F4: 1ST ORDER QUANTITY. | G4: ='WILD ONE'!K3+'WILD ONE'!K44 -> 4134 | H4: ='WILD ONE'!L3+'WILD ONE'!L44 -> 4134 | I4: ='WILD ONE'!M3+'WILD ONE'!M44 -> 6201 | J4: ='WILD ONE'!N3+'WILD ONE'!N44 -> 6201 | K4: ='WILD ONE'!O3+'WILD ONE'!O44 -> 4134 | L4: =SUM(G4:K4) -> 24804
F5: 1ST CUTTING QUANTITY. | G5: ='WILD ONE'!K40+'WILD ONE'!K119 -> 4176 | H5: ='WILD ONE'!L40+'WILD ONE'!L119 -> 4176 | I5: ='WILD ONE'!M40+'WILD ONE'!M119 -> 6264 | J5: ='WILD ONE'!N40+'WILD ONE'!N119 -> 6264 | K5: ='WILD ONE'!O40+'WILD ONE'!O119 -> 4176 | L5: =SUM(G5:K5) -> 25056
F6: ORDER QTY. TO CUTTING BALANCE= | G6: =G5-G4 -> 42 | H6: =H5-H4 -> 42 | I6: =I5-I4 -> 63 | J6: =J5-J4 -> 63 | K6: =K5-K4 -> 42 | L6: =SUM(G6:K6) -> 252
F7: INPUT QUANTITY. | G7: ='WILD ONE'!K40+'WILD ONE'!K119 -> 4176 | H7: ='WILD ONE'!L40+'WILD ONE'!L119 -> 4176 | I7: ='WILD ONE'!M40+'WILD ONE'!M119 -> 6264 | J7: ='WILD ONE'!N40+'WILD ONE'!N119 -> 6264 | K7: ='WILD ONE'!O40+'WILD ONE'!O119 -> 4176 | L7: =SUM(G7:K7) -> 25056
F8: CUTTING TO INPUT BALANCE= | G8: =G7-G5 -> 0 | H8: =H7-H5 -> 0 | I8: =I7-I5 -> 0 | J8: =J7-J5 -> 0 | K8: =K7-K5 -> 0 | L8: =SUM(G8:K8) -> 0
B10: Buyer | C10: Style | D10: P.O No. | E10: Color | F10: Description | G10: XS | H10: S | I10: M | J10: L | K10: XL | L10: Total | M10: REMARKS
B11: GREENSOURCE | C11: SHACKET-G074 | D11: 14220+22 | E11: WANDER IKAT | F11: 1ST ORDER QUANTITY. | G11: ='WANDER IKAT'!K3+'WANDER IKAT'!K45 -> 4134 | H11: ='WANDER IKAT'!L3+'WANDER IKAT'!L45 -> 4134 | I11: ='WANDER IKAT'!M3+'WANDER IKAT'!M45 -> 4134 | J11: ='WANDER IKAT'!N3+'WANDER IKAT'!N45 -> 6201 | K11: ='WANDER IKAT'!O3+'WANDER IKAT'!O45 -> 4134 | L11: =SUM(G11:K11) -> 22737
F12: 1ST CUTTING QUANTITY. | G12: ='WANDER IKAT'!K41+'WANDER IKAT'!K116 -> 4012 | H12: ='WANDER IKAT'!L41+'WANDER IKAT'!L116 -> 4012 | I12: ='WANDER IKAT'!M41+'WANDER IKAT'!M116 -> 4012 | J12: ='WANDER IKAT'!N41+'WANDER IKAT'!N116 -> 6018 | K12: ='WANDER IKAT'!O41+'WANDER IKAT'!O116 -> 4012 | L12: =SUM(G12:K12) -> 22066
F13: ORDER QTY. TO CUTTING BALANCE= | G13: =G12-G11 -> -122 | H13: =H12-H11 -> -122 | I13: =I12-I11 -> -122 | J13: =J12-J11 -> -183 | K13: =K12-K11 -> -122 | L13: =SUM(G13:K13) -> -671
F14: INPUT QUANTITY. | G14: ='WANDER IKAT'!K41+'WANDER IKAT'!K116 -> 4012 | H14: ='WANDER IKAT'!L41+'WANDER IKAT'!L116 -> 4012 | I14: ='WANDER IKAT'!M41+'WANDER IKAT'!M116 -> 4012 | J14: ='WANDER IKAT'!N41+'WANDER IKAT'!N116 -> 6018 | K14: ='WANDER IKAT'!O41+'WANDER IKAT'!O116 -> 4012 | L14: =SUM(G14:K14) -> 22066
F15: CUTTING TO INPUT BALANCE= | G15: =G14-G12 -> 0 | H15: =H14-H12 -> 0 | I15: =I14-I12 -> 0 | J15: =J14-J12 -> 0 | K15: =K14-K12 -> 0 | L15: =SUM(G15:K15) -> 0
B17: Buyer | C17: Style | D17: P.O No. | E17: Color | F17: Description | G17: XS | H17: S | I17: M | J17: L | K17: XL | L17: Total | M17: REMARKS
B18: GREENSOURCE | C18: SHACKET-G074 | D18: 14220+22 | E18: HEART PARADE | F18: 1ST ORDER QUANTITY. | G18: ='HEART PARADE'!K3+'HEART PARADE'!K45 -> 6201 | H18: ='HEART PARADE'!L3+'HEART PARADE'!L45 -> 4134 | I18: ='HEART PARADE'!M3+'HEART PARADE'!M45 -> 4134 | J18: ='HEART PARADE'!N3+'HEART PARADE'!N45 -> 4134 | K18: ='HEART PARADE'!O3+'HEART PARADE'!O45 -> 4134 | L18: =SUM(G18:K18) -> 22737
F19: 1ST CUTTING QUANTITY. | G19: ='HEART PARADE'!K41+'HEART PARADE'!K108 -> 5907 | H19: ='HEART PARADE'!L41+'HEART PARADE'!L108 -> 3938 | I19: ='HEART PARADE'!M41+'HEART PARADE'!M108 -> 3938 | J19: ='HEART PARADE'!N41+'HEART PARADE'!N108 -> 3938 | K19: ='HEART PARADE'!O41+'HEART PARADE'!O108 -> 3938 | L19: =SUM(G19:K19) -> 21659
F20: ORDER QTY. TO CUTTING BALANCE= | G20: =G19-G18 -> -294 | H20: =H19-H18 -> -196 | I20: =I19-I18 -> -196 | J20: =J19-J18 -> -196 | K20: =K19-K18 -> -196 | L20: =SUM(G20:K20) -> -1078
F21: INPUT QUANTITY. | G21: ='HEART PARADE'!K41+'HEART PARADE'!K108 -> 5907 | H21: ='HEART PARADE'!L41+'HEART PARADE'!L108 -> 3938 | I21: ='HEART PARADE'!M41+'HEART PARADE'!M108 -> 3938 | J21: ='HEART PARADE'!N41+'HEART PARADE'!N108 -> 3938 | K21: ='HEART PARADE'!O41+'HEART PARADE'!O108 -> 3938 | L21: =SUM(G21:K21) -> 21659
F22: CUTTING TO INPUT BALANCE= | G22: =G21-G19 -> 0 | H22: =H21-H19 -> 0 | I22: =I21-I19 -> 0 | J22: =J21-J19 -> 0 | K22: =K21-K19 -> 0 | L22: =SUM(G22:K22) -> 0
B24: Buyer | C24: Style | D24: P.O No. | E24: Color | F24: Description | G24: XS | H24: S | I24: M | J24: L | K24: XL | L24: Total | M24: REMARKS
B25: GREENSOURCE | C25: SHACKET-G074 | D25: 14220+22 | E25: ANTIQUE ROSE | F25: 1ST ORDER QUANTITY. | G25: ='ANTIQUE ROSE'!K3+'ANTIQUE ROSE'!K38 -> 4134 | H25: ='ANTIQUE ROSE'!L3+'ANTIQUE ROSE'!L38 -> 2067 | I25: ='ANTIQUE ROSE'!M3+'ANTIQUE ROSE'!M38 -> 6201 | J25: ='ANTIQUE ROSE'!N3+'ANTIQUE ROSE'!N38 -> 6201 | K25: ='ANTIQUE ROSE'!O3+'ANTIQUE ROSE'!O38 -> 6201 | L25: =SUM(G25:K25) -> 24804
F26: 1ST CUTTING QUANTITY. | G26: ='ANTIQUE ROSE'!K34+'ANTIQUE ROSE'!K94 -> 3914 | H26: ='ANTIQUE ROSE'!L34+'ANTIQUE ROSE'!L94 -> 1957 | I26: ='ANTIQUE ROSE'!M34+'ANTIQUE ROSE'!M94 -> 5871 | J26: ='ANTIQUE ROSE'!N34+'ANTIQUE ROSE'!N94 -> 5871 | K26: ='ANTIQUE ROSE'!O34+'ANTIQUE ROSE'!O94 -> 5871 | L26: =SUM(G26:K26) -> 23484
F27: ORDER QTY. TO CUTTING BALANCE= | G27: =G26-G25 -> -220 | H27: =H26-H25 -> -110 | I27: =I26-I25 -> -330 | J27: =J26-J25 -> -330 | K27: =K26-K25 -> -330 | L27: =SUM(G27:K27) -> -1320
F28: INPUT QUANTITY. | G28: ='ANTIQUE ROSE'!K34+'ANTIQUE ROSE'!K94 -> 3914 | H28: ='ANTIQUE ROSE'!L34+'ANTIQUE ROSE'!L94 -> 1957 | I28: ='ANTIQUE ROSE'!M34+'ANTIQUE ROSE'!M94 -> 5871 | J28: ='ANTIQUE ROSE'!N34+'ANTIQUE ROSE'!N94 -> 5871 | K28: ='ANTIQUE ROSE'!O34+'ANTIQUE ROSE'!O94 -> 5871 | L28: =SUM(G28:K28) -> 23484
F29: CUTTING TO INPUT BALANCE= | G29: =G28-G26 -> 0 | H29: =H28-H26 -> 0 | I29: =I28-I26 -> 0 | J29: =J28-J26 -> 0 | K29: =K28-K26 -> 0 | L29: =SUM(G29:K29) -> 0
K32: 1ST ORDER QUANTITY. | L32: =L18+L11+L25+L4 -> 95082
K33: 1ST CUTTING QUANTITY. | L33: =L19+L12+L26+L5 -> 92265
K34: ORDER QTY. TO CUTTING BALANCE= | L34: =L33-L32 -> -2817
K35: INPUT QUANTITY. | L35: =L21+L14+L28+L7 -> 92265
K36: CUTTING TO INPUT BALANCE= | L36: =L35-L33 -> 0

Sheet 2ND ORDER
B1: 2ND ORDER | F1: SILVER COMPOSITE TEXTILE MILLS LTD. (UNIT-01)
E2: 1ST ORDER CUTTING & INPUT REPORT | L2: 46194
B3: Buyer | C3: Style | D3: P.O No. | E3: Color | F3: Description | G3: XS | H3: S | I3: M | J3: L | K3: XL | L3: Total | M3: REMARKS
B4: GREENSOURCE | C4: SHACKET-G074 | D4: 14223 | E4: WILD ONE | F4: 2ND ORDER QUANTITY. | G4: ='WILD ONE'!K123 -> 2612 | H4: ='WILD ONE'!L123 -> 2612 | I4: ='WILD ONE'!M123 -> 3918 | J4: ='WILD ONE'!N123 -> 3918 | K4: ='WILD ONE'!O123 -> 2612 | L4: =SUM(G4:K4) -> 15672
F5: 2ND CUTTING QUANTITY. | G5: ='WILD ONE'!K192 -> 2638 | H5: ='WILD ONE'!L192 -> 2638 | I5: ='WILD ONE'!M192 -> 3957 | J5: ='WILD ONE'!N192 -> 3957 | K5: ='WILD ONE'!O192 -> 2638 | L5: =SUM(G5:K5) -> 15828
F6: ORDER QTY. TO CUTTING BALANCE= | G6: =G5-G4 -> 26 | H6: =H5-H4 -> 26 | I6: =I5-I4 -> 39 | J6: =J5-J4 -> 39 | K6: =K5-K4 -> 26 | L6: =SUM(G6:K6) -> 156
F7: INPUT QUANTITY. | G7: ='WILD ONE'!K238 -> 1680 | H7: ='WILD ONE'!L238 -> 1680 | I7: ='WILD ONE'!M238 -> 2520 | J7: ='WILD ONE'!N238 -> 2520 | K7: ='WILD ONE'!O238 -> 1680 | L7: =SUM(G7:K7) -> 10080
F8: CUTTING TO INPUT BALANCE= | G8: =G7-G5 -> -958 | H8: =H7-H5 -> -958 | I8: =I7-I5 -> -1437 | J8: =J7-J5 -> -1437 | K8: =K7-K5 -> -958 | L8: =SUM(G8:K8) -> -5748
B10: Buyer | C10: Style | D10: P.O No. | E10: Color | F10: Description | G10: XS | H10: S | I10: M | J10: L | K10: XL | L10: Total | M10: REMARKS
B11: GREENSOURCE | C11: SHACKET-G074 | D11: 14223 | E11: WANDER IKAT | F11: 2ND ORDER QUANTITY. | G11: ='WANDER IKAT'!K120 -> 2612 | H11: ='WANDER IKAT'!L120 -> 2612 | I11: ='WANDER IKAT'!M120 -> 2612 | J11: ='WANDER IKAT'!N120 -> 3918 | K11: ='WANDER IKAT'!O120 -> 2612 | L11: =SUM(G11:K11) -> 14366
F12: 2ND CUTTING QUANTITY. | G12: ='WANDER IKAT'!K189 -> 2638 | H12: ='WANDER IKAT'!L189 -> 2638 | I12: ='WANDER IKAT'!M189 -> 2638 | J12: ='WANDER IKAT'!N189 -> 3957 | K12: ='WANDER IKAT'!O189 -> 2638 | L12: =SUM(G12:K12) -> 14509
F13: ORDER QTY. TO CUTTING BALANCE= | G13: =G12-G11 -> 26 | H13: =H12-H11 -> 26 | I13: =I12-I11 -> 26 | J13: =J12-J11 -> 39 | K13: =K12-K11 -> 26 | L13: =SUM(G13:K13) -> 143 | O13: INP -630
F14: INPUT QUANTITY. | G14: ='WANDER IKAT'!K252 -> 2404 | H14: ='WANDER IKAT'!L252 -> 2404 | I14: ='WANDER IKAT'!M252 -> 2404 | J14: ='WANDER IKAT'!N252 -> 3606 | K14: ='WANDER IKAT'!O252 -> 2404 | L14: =SUM(G14:K14) -> 13222
F15: CUTTING TO INPUT BALANCE= | G15: =G14-G12 -> -234 | H15: =H14-H12 -> -234 | I15: =I14-I12 -> -234 | J15: =J14-J12 -> -351 | K15: =K14-K12 -> -234 | L15: =SUM(G15:K15) -> -1287
B17: Buyer | C17: Style | D17: P.O No. | E17: Color | F17: Description | G17: XS | H17: S | I17: M | J17: L | K17: XL | L17: Total | M17: REMARKS
B18: GREENSOURCE | C18: SHACKET-G074 | D18: 14223 | E18: HEART PARADE | F18: 2ND ORDER QUANTITY. | G18: ='HEART PARADE'!K112 -> 3918 | H18: ='HEART PARADE'!L112 -> 2612 | I18: ='HEART PARADE'!M112 -> 2612 | J18: ='HEART PARADE'!N112 -> 2612 | K18: ='HEART PARADE'!O112 -> 2612 | L18: =SUM(G18:K18) -> 14366
F19: 2ND CUTTING QUANTITY. | G19: ='HEART PARADE'!K177 -> 3957 | H19: ='HEART PARADE'!L177 -> 2638 | I19: ='HEART PARADE'!M177 -> 2638 | J19: ='HEART PARADE'!N177 -> 2638 | K19: ='HEART PARADE'!O177 -> 2638 | L19: =SUM(G19:K19) -> 14509
F20: ORDER QTY. TO CUTTING BALANCE= | G20: =G19-G18 -> 39 | H20: =H19-H18 -> 26 | I20: =I19-I18 -> 26 | J20: =J19-J18 -> 26 | K20: =K19-K18 -> 26 | L20: =SUM(G20:K20) -> 143
F21: INPUT QUANTITY. | G21: ='HEART PARADE'!K232 -> 3879 | H21: ='HEART PARADE'!L232 -> 2586 | I21: ='HEART PARADE'!M232 -> 2586 | J21: ='HEART PARADE'!N232 -> 2586 | K21: ='HEART PARADE'!O232 -> 2586 | L21: =SUM(G21:K21) -> 14223
F22: CUTTING TO INPUT BALANCE= | G22: =G21-G19 -> -78 | H22: =H21-H19 -> -52 | I22: =I21-I19 -> -52 | J22: =J21-J19 -> -52 | K22: =K21-K19 -> -52 | L22: =SUM(G22:K22) -> -286
B24: Buyer | C24: Style | D24: P.O No. | E24: Color | F24: Description | G24: XS | H24: S | I24: M | J24: L | K24: XL | L24: Total | M24: REMARKS
B25: GREENSOURCE | C25: SHACKET-G074 | D25: 14223 | E25: ANTIQUE ROSE | F25: 2ND ORDER QUANTITY. | G25: ='ANTIQUE ROSE'!K98 -> 2612 | H25: ='ANTIQUE ROSE'!L98 -> 1306 | I25: ='ANTIQUE ROSE'!M98 -> 3918 | J25: ='ANTIQUE ROSE'!N98 -> 3918 | K25: ='ANTIQUE ROSE'!O98 -> 3918 | L25: =SUM(G25:K25) -> 15672
F26: 2ND CUTTING QUANTITY. | G26: ='ANTIQUE ROSE'!K154 -> 2638 | H26: ='ANTIQUE ROSE'!L154 -> 1319 | I26: ='ANTIQUE ROSE'!M154 -> 3957 | J26: ='ANTIQUE ROSE'!N154 -> 3957 | K26: ='ANTIQUE ROSE'!O154 -> 3957 | L26: =SUM(G26:K26) -> 15828
F27: ORDER QTY. TO CUTTING BALANCE= | G27: =G26-G25 -> 26 | H27: =H26-H25 -> 13 | I27: =I26-I25 -> 39 | J27: =J26-J25 -> 39 | K27: =K26-K25 -> 39 | L27: =SUM(G27:K27) -> 156
F28: INPUT QUANTITY. | G28: ='ANTIQUE ROSE'!K202 -> 2302 | H28: ='ANTIQUE ROSE'!L202 -> 1151 | I28: ='ANTIQUE ROSE'!M202 -> 3453 | J28: ='ANTIQUE ROSE'!N202 -> 3453 | K28: ='ANTIQUE ROSE'!O202 -> 3453 | L28: =SUM(G28:K28) -> 13812
F29: CUTTING TO INPUT BALANCE= | G29: =G28-G26 -> -336 | H29: =H28-H26 -> -168 | I29: =I28-I26 -> -504 | J29: =J28-J26 -> -504 | K29: =K28-K26 -> -504 | L29: =SUM(G29:K29) -> -2016
K32: 2ND ORDER QUANTITY. | L32: =L18+L11+L25+L4 -> 60076
K33: 2ND CUTTING QUANTITY. | L33: =L19+L12+L26+L5 -> 60674
K34: ORDER QTY. TO CUTTING BALANCE= | L34: =L33-L32 -> 598
K35: INPUT QUANTITY. | L35: =L21+L14+L28+L7 -> 51337
K36: CUTTING TO INPUT BALANCE= | L36: =L35-L33 -> -9337
K38: ORDER QUANTITY. | L38: =L32+'1ST ORDER'!L32 -> 155158
K39: CUTTING QUANTITY. | L39: =L33+'1ST ORDER'!L33 -> 152939
K40: =K34 -> ORDER QTY. TO CUTTING BALANCE= | L40: =L39-L38 -> -2219
K41: =K35 -> INPUT QUANTITY. | L41: =L35+'1ST ORDER'!L35 -> 143602
K42: =K36 -> CUTTING TO INPUT BALANCE= | L42: =L41-L39 -> -9337

Sheet ANTIQUE ROSE
I1: SILVER COMPOSITE TEXTILE MILS LIMITETD. (UNIT-01)
I2: CUTTING SUMMARY
J3: Size Wise Order Breakdown: | K3: 1306 | L3: 653 | M3: 1959 | N3: 1959 | O3: 1959 | P3: =SUM(K3:O3) -> 7836
A4: Buyer | B4: Style | C4: P.O No. | D4: Color | E4: P.O Total | F4: Label | G4: Date | H4: Lay Qty | I4: No of Ratio | J4: Cut No. | K4: XS | L4: S | M4: M | N4: L | O4: XL | P4: Total | Q4: Grand Total | R4: REMARKS
A5: GREENSOURCE | B5: SHACKET-G074 | C5: 14220 | D5: ANTIQUE ROSE | E5: =P3 -> 7836 | G5: 46152 | H5: 16 | J5: 1 | K5: 32 | L5: 16 | M5: =16*3 -> 48 | N5: =16*3 -> 48 | O5: =16*3 -> 48 | P5: =IF(G5="","",SUM(K5:O5)) -> 192 | Q5: =IF(P5="","",P5) -> 192 | R5: SHADE-A
A6: FW26 | D6: PINK | G6: 46153 | H6: 15 | J6: 2 | K6: 30 | L6: 15 | M6: 45 | N6: 45 | O6: 45 | P6: =IF(G6="","",SUM(K6:O6)) -> 180 | Q6: =IF(P6="","",Q5+P6) -> 372 | R6: SHADE-A
G7: 46153 | H7: 25 | J7: 3 | K7: 50 | L7: 25 | M7: 75 | N7: 75 | O7: 75 | P7: =IF(G7="","",SUM(K7:O7)) -> 300 | Q7: =IF(P7="","",Q6+P7) -> 672 | R7: SHADE-A
G8: 46154 | H8: 20 | J8: 4 | K8: 40 | L8: 20 | M8: 60 | N8: 60 | O8: 60 | P8: =IF(G8="","",SUM(K8:O8)) -> 240 | Q8: =IF(P8="","",Q7+P8) -> 912 | R8: SHADE-A
G9: 46154 | H9: 25 | J9: 5 | K9: =25*2 -> 50 | L9: 25 | M9: 75 | N9: 75 | O9: 75 | P9: =IF(G9="","",SUM(K9:O9)) -> 300 | Q9: =IF(P9="","",Q8+P9) -> 1212 | R9: SHADE-A
G10: 46154 | H10: 25 | J10: 6 | K10: 50 | L10: 25 | M10: 75 | N10: 75 | O10: 75 | P10: =IF(G10="","",SUM(K10:O10)) -> 300 | Q10: =IF(P10="","",Q9+P10) -> 1512 | R10: SHADE-A
G11: 46155 | H11: 18 | J11: 7 | K11: 36 | L11: 18 | M11: =18*3 -> 54 | N11: 54 | O11: 54 | P11: =IF(G11="","",SUM(K11:O11)) -> 216 | Q11: =IF(P11="","",Q10+P11) -> 1728 | R11: SHADE-A
G12: 46156 | H12: 25 | J12: 8 | K12: 50 | L12: 25 | M12: 75 | N12: 75 | O12: 75 | P12: =IF(G12="","",SUM(K12:O12)) -> 300 | Q12: =IF(P12="","",Q11+P12) -> 2028 | R12: SHADE-A
G13: 46156 | H13: 25 | J13: 9 | K13: 50 | L13: 25 | M13: 75 | N13: 75 | O13: 75 | P13: =IF(G13="","",SUM(K13:O13)) -> 300 | Q13: =IF(P13="","",Q12+P13) -> 2328 | R13: SHADE-A
G14: 46156 | H14: 25 | J14: 10 | K14: 50 | L14: 25 | M14: 75 | N14: 75 | O14: 75 | P14: =IF(G14="","",SUM(K14:O14)) -> 300 | Q14: =IF(P14="","",Q13+P14) -> 2628 | R14: SHADE-A
G15: 46156 | H15: 25 | J15: 11 | K15: 50 | L15: 25 | M15: 75 | N15: 75 | O15: 75 | P15: =IF(G15="","",SUM(K15:O15)) -> 300 | Q15: =IF(P15="","",Q14+P15) -> 2928 | R15: SHADE-A
G16: 46158 | H16: 25 | J16: 12 | K16: 50 | L16: 25 | M16: 75 | N16: 75 | O16: 75 | P16: =IF(G16="","",SUM(K16:O16)) -> 300 | Q16: =IF(P16="","",Q15+P16) -> 3228 | R16: SHADE-A
G17: 46158 | H17: 25 | J17: 13 | K17: 50 | L17: 25 | M17: 75 | N17: 75 | O17: 75 | P17: =IF(G17="","",SUM(K17:O17)) -> 300 | Q17: =IF(P17="","",Q16+P17) -> 3528 | R17: SHADE-A
G18: 46159 | H18: 20 | J18: 14 | K18: 40 | L18: 20 | M18: 60 | N18: 60 | O18: 60 | P18: =IF(G18="","",SUM(K18:O18)) -> 240 | Q18: =IF(P18="","",Q17+P18) -> 3768 | R18: SHADE-A
G19: 46159 | H19: 25 | J19: 15 | K19: 50 | L19: 25 | M19: 75 | N19: 75 | O19: 75 | P19: =IF(G19="","",SUM(K19:O19)) -> 300 | Q19: =IF(P19="","",Q18+P19) -> 4068 | R19: SHADE-A
G20: 46159 | H20: 25 | J20: 16 | K20: 50 | L20: 25 | M20: 75 | N20: 75 | O20: 75 | P20: =IF(G20="","",SUM(K20:O20)) -> 300 | Q20: =IF(P20="","",Q19+P20) -> 4368 | R20: SHADE-A
G21: 46160 | H21: 25 | J21: 17 | K21: 50 | L21: 25 | M21: 75 | N21: 75 | O21: 75 | P21: =IF(G21="","",SUM(K21:O21)) -> 300 | Q21: =IF(P21="","",Q20+P21) -> 4668 | R21: SHADE-A
G22: 46160 | H22: 25 | J22: 18 | K22: 50 | L22: 25 | M22: 75 | N22: 75 | O22: 75 | P22: =IF(G22="","",SUM(K22:O22)) -> 300 | Q22: =IF(P22="","",Q21+P22) -> 4968 | R22: SHADE-A
G23: 46160 | H23: 25 | J23: 19 | K23: 50 | L23: 25 | M23: 75 | N23: 75 | O23: 75 | P23: =IF(G23="","",SUM(K23:O23)) -> 300 | Q23: =IF(P23="","",Q22+P23) -> 5268 | R23: SHADE-A
... G31: 46162 | H31: 25 | J31: 27 | K31: 50 | L31: 25 | M31: 75 | N31: 75 | O31: 75 | P31: =IF(G31="","",SUM(K31:O31)) -> 300 | Q31: =IF(P31="","",Q30+P31) -> 7668 | R31: SHADE-A
G32: 46162 | H32: 21 | J32: 28 | K32: 42 | L32: 21 | M32: =21*3 -> 63 | N32: 63 | O32: 63 | P32: =IF(G32="","",SUM(K32:O32)) -> 252 | Q32: =IF(P32="","",Q31+P32) -> 7920 | R32: SHADE-A
P33: =IF(G33="","",SUM(K33:O33)) | Q33: =IF(P33="","",#REF!+P33)
J34: Total: | K34: =SUM(K5:K33) -> 1320 | L34: =SUM(L5:L33) -> 660 | M34: =SUM(M5:M33) -> 1980 | N34: =SUM(N5:N33) -> 1980 | O34: =SUM(O5:O33) -> 1980 | P34: =SUM(K34:O34) -> 7920
J35: Excess Cut: | K35: =IF(K3="","",K34-K3) -> 14 | L35: =IF(L3="","",L34-L3) -> 7 | M35: =IF(M3="","",M34-M3) -> 21 | N35: =IF(N3="","",N34-N3) -> 21 | O35: =IF(O3="","",O34-O3) -> 21 | P35: =SUM(K35:O35) -> 84
J36: 26 | K36: =SUM(K5:K30) -> 1228 | L36: =SUM(L5:L30) -> 614 | M36: =SUM(M5:M30) -> 1842 | N36: =SUM(N5:N30) -> 1842 | O36: =SUM(O5:O30) -> 1842 | P36: =SUM(P5:P30) -> 7368
I37: CUTTING SUMMARY
J38: Size Wise Order Breakdown: | K38: 2828 | L38: 1414 | M38: 4242 | N38: 4242 | O38: 4242 | P38: =SUM(K38:O38) -> 16968
A39: Buyer | B39: Style | C39: P.O No. | D39: Color | E39: P.O Total | F39: Label | G39: Date | H39: Lay Qty | I39: No of Ratio | J39: Cut No. | K39: XS | L39: S | M39: M | N39: L | O39: XL | P39: Total | Q39: Grand Total | R39: REMARKS
A40: GREENSOURCE | B40: SHACKET-G074 | C40: 14222 | D40: ANTIQUE ROSE | E40: =P38 -> 16968 | G40: 46162 | H40: 25 | J40: 29 | K40: 50 | L40: 25 | M40: 75 | N40: 75 | O40: 75 | P40: =IF(G40="","",SUM(K40:O40)) -> 300 | Q40: =IF(P40="","",P40) -> 300 | R40: SHADE-A
A41: FW26 | D41: PINK | G41: 46162 | H41: 25 | J41: 30 | K41: 50 | L41: 25 | M41: 75 | N41: 75 | O41: 75 | P41: =IF(G41="","",SUM(K41:O41)) -> 300 | Q41: =IF(P41="","",P41+Q40) -> 600 | R41: SHADE-A
G42: 46162 | H42: 25 | J42: 31 | K42: 50 | L42: 25 | M42: 75 | N42: 75 | O42: 75 | P42: =IF(G42="","",SUM(K42:O42)) -> 300 | Q42: =IF(P42="","",P42+Q41) -> 900 | R42: SHADE-A
G43: 46162 | H43: 25 | J43: 32 | K43: 50 | L43: 25 | M43: 75 | N43: 75 | O43: 75 | P43: =IF(G43="","",SUM(K43:O43)) -> 300 | Q43: =IF(P43="","",P43+Q42) -> 1200 | R43: SHADE-A
G44: 46163 | H44: 25 | J44: 33 | K44: 50 | L44: 25 | M44: 75 | N44: 75 | O44: 75 | P44: =IF(G44="","",SUM(K44:O44)) -> 300 | Q44: =IF(P44="","",P44+Q43) -> 1500 | R44: SHADE-A
G45: 46163 | H45: 25 | J45: 34 | K45: 50 | L45: 25 | M45: 75 | N45: 75 | O45: 75 | P45: =IF(G45="","",SUM(K45:O45)) -> 300 | Q45: =IF(P45="","",P45+Q44) -> 1800 | R45: SHADE-A
G46: 46163 | H46: 25 | J46: 35 | K46: 50 | L46: 25 | M46: 75 | N46: 75 | O46: 75 | P46: =IF(G46="","",SUM(K46:O46)) -> 300 | Q46: =IF(P46="","",P46+Q45) -> 2100 | R46: SHADE-A
G47: 46163 | H47: 25 | J47: 36 | K47: 50 | L47: 25 | M47: 75 | N47: 75 | O47: 75 | P47: =IF(G47="","",SUM(K47:O47)) -> 300 | Q47: =IF(P47="","",P47+Q46) -> 2400 | R47: SHADE-A
...

Sheet HEART PARADE
I1: SILVER COMPOSITE TEXTILE MILS LIMITETD. (UNIT-01)
I2: CUTTING SUMMARY
J3: Size Wise Order Breakdown: | K3: 1959 | L3: 1306 | M3: 1306 | N3: 1306 | O3: 1306 | P3: =SUM(K3:O3) -> 7183
A4: Buyer | B4: Style | C4: P.O No. | D4: Color | E4: P.O Total | F4: Label | G4: Date | H4: Lay Qty | I4: No of Ratio | J4: Cut No. | K4: XS | L4: S | M4: M | N4: L | O4: XL | P4: Total | Q4: Grand Total | R4: REMARKS
A5: GREENSOURCE | B5: SHACKET-G074 | C5: 14220 | D5: HEART PARADE | E5: =P3 -> 7183 | G5: 46152 | H5: 15 | J5: 1 | K5: 45 | L5: 30 | M5: 30 | N5: 30 | O5: 30 | P5: =IF(G5="","",SUM(K5:O5)) -> 165 | Q5: =IF(P5="","",P5) -> 165 | R5: SHADE-A
A6: FW26 | D6: CREAM | G6: 46153 | H6: 15 | J6: 2 | K6: 45 | L6: 30 | M6: 30 | N6: 30 | O6: 30 | P6: =IF(G6="","",SUM(K6:O6)) -> 165 | Q6: =IF(P6="","",Q5+P6) -> 330 | R6: SHADE-A
G7: 46153 | H7: 15 | J7: 3 | K7: 45 | L7: 30 | M7: 30 | N7: 30 | O7: 30 | P7: =IF(G7="","",SUM(K7:O7)) -> 165 | Q7: =IF(P7="","",Q6+P7) -> 495 | R7: SHADE-A
G8: 46154 | H8: 18 | J8: 4 | K8: 54 | L8: 36 | M8: 36 | N8: 36 | O8: 36 | P8: =IF(G8="","",SUM(K8:O8)) -> 198 | Q8: =IF(P8="","",Q7+P8) -> 693 | R8: SHADE-A
G9: 46154 | H9: 18 | J9: 5 | K9: 54 | L9: 36 | M9: 36 | N9: 36 | O9: 36 | P9: =IF(G9="","",SUM(K9:O9)) -> 198 | Q9: =IF(P9="","",Q8+P9) -> 891 | R9: SHADE-A
G10: 46155 | H10: 15 | J10: 6 | K10: 45 | L10: 30 | M10: 30 | N10: 30 | O10: 30 | P10: =IF(G10="","",SUM(K10:O10)) -> 165 | Q10: =IF(P10="","",Q9+P10) -> 1056 | R10: SHADE-A
G11: 46155 | H11: 15 | J11: 7 | K11: 45 | L11: 30 | M11: 30 | N11: 30 | O11: 30 | P11: =IF(G11="","",SUM(K11:O11)) -> 165 | Q11: =IF(P11="","",Q10+P11) -> 1221 | R11: SHADE-A
G12: 46155 | H12: 14 | J12: 8 | K12: 42 | L12: 28 | M12: 28 | N12: 28 | O12: 28 | P12: =IF(G12="","",SUM(K12:O12)) -> 154 | Q12: =IF(P12="","",Q11+P12) -> 1375 | R12: SHADE-A
G13: 46155 | H13: 20 | J13: 9 | K13: 60 | L13: 40 | M13: 40 | N13: 40 | O13: 40 | P13: =IF(G13="","",SUM(K13:O13)) -> 220 | Q13: =IF(P13="","",Q12+P13) -> 1595 | R13: SHADE-A
G14: 46155 | H14: 20 | J14: 10 | K14: 60 | L14: 40 | M14: 40 | N14: 40 | O14: 40 | P14: =IF(G14="","",SUM(K14:O14)) -> 220 | Q14: =IF(P14="","",Q13+P14) -> 1815 | R14: SHADE-A
G15: 46155 | H15: 20 | J15: 11 | K15: 60 | L15: 40 | M15: 40 | N15: 40 | O15: 40 | P15: =IF(G15="","",SUM(K15:O15)) -> 220 | Q15: =IF(P15="","",Q14+P15) -> 2035 | R15: SHADE-A
G16: 46155 | H16: 20 | J16: 12 | K16: 60 | L16: 40 | M16: 40 | N16: 40 | O16: 40 | P16: =IF(G16="","",SUM(K16:O16)) -> 220 | Q16: =IF(P16="","",Q15+P16) -> 2255 | R16: SHADE-A
G17: 46156 | H17: 20 | J17: 13 | K17: =20*3 -> 60 | L17: =20*2 -> 40 | M17: =20*2 -> 40 | N17: =20*2 -> 40 | O17: =20*2 -> 40 | P17: =IF(G17="","",SUM(K17:O17)) -> 220 | Q17: =IF(P17="","",Q16+P17) -> 2475 | R17: SHADE-A
G18: 46156 | H18: 20 | J18: 14 | K18: 60 | L18: 40 | M18: 40 | N18: 40 | O18: 40 | P18: =IF(G18="","",SUM(K18:O18)) -> 220 | Q18: =IF(P18="","",Q17+P18) -> 2695 | R18: SHADE-A
G19: 46158 | H19: 20 | J19: 15 | K19: 60 | L19: 40 | M19: 40 | N19: 40 | O19: 40 | P19: =IF(G19="","",SUM(K19:O19)) -> 220 | Q19: =IF(P19="","",Q18+P19) -> 2915 | R19: SHADE-A
G20: 46158 | H20: 20 | J20: 16 | K20: 60 | L20: 40 | M20: 40 | N20: 40 | O20: 40 | P20: =IF(G20="","",SUM(K20:O20)) -> 220 | Q20: =IF(P20="","",Q19+P20) -> 3135 | R20: SHADE-A
G21: 46158 | H21: 20 | J21: 17 | K21: 60 | L21: 40 | M21: 40 | N21: 40 | O21: 40 | P21: =IF(G21="","",SUM(K21:O21)) -> 220 | Q21: =IF(P21="","",Q20+P21) -> 3355 | R21: SHADE-A
G22: 46158 | H22: 20 | J22: 18 | K22: 60 | L22: 40 | M22: 40 | N22: 40 | O22: 40 | P22: =IF(G22="","",SUM(K22:O22)) -> 220 | Q22: =IF(P22="","",Q21+P22) -> 3575 | R22: SHADE-A
G23: 46158 | H23: 20 | J23: 19 | K23: 60 | L23: 40 | M23: 40 | N23: 40 | O23: 40 | P23: =IF(G23="","",SUM(K23:O23)) -> 220 | Q23: =IF(P23="","",Q22+P23) -> 3795 | R23: SHADE-A
G24: 46159 | H24: 20 | J24: 20 | K24: 60 | L24: 40 | M24: 40 | N24: 40 | O24: 40 | P24: =IF(G24="","",SUM(K24:O24)) -> 220 | Q24: =IF(P24="","",Q23+P24) -> 4015 | R24: SHADE-A
G25: 46159 | H25: 20 | J25: 21 | K25: 60 | L25: 40 | M25: 40 | N25: 40 | O25: 40 | P25: =IF(G25="","",SUM(K25:O25)) -> 220 | Q25: =IF(P25="","",Q24+P25) -> 4235 | R25: SHADE-A
G26: 46159 | H26: 20 | J26: 22 | K26: 60 | L26: 40 | M26: 40 | N26: 40 | O26: 40 | P26: =IF(G26="","",SUM(K26:O26)) -> 220 | Q26: =IF(P26="","",Q25+P26) -> 4455 | R26: SHADE-A
G27: 46159 | H27: 20 | J27: 23 | K27: 60 | L27: 40 | M27: 40 | N27: 40 | O27: 40 | P27: =IF(G27="","",SUM(K27:O27)) -> 220 | Q27: =IF(P27="","",Q26+P27) -> 4675 | R27: SHADE-A
G28: 46159 | H28: 20 | J28: 24 | K28: 60 | L28: 40 | M28: 40 | N28: 40 | O28: 40 | P28: =IF(G28="","",SUM(K28:O28)) -> 220 | Q28: =IF(P28="","",Q27+P28) -> 4895 | R28: SHADE-A
G29: 46160 | H29: 20 | J29: 25 | K29: 60 | L29: 40 | M29: 40 | N29: 40 | O29: 40 | P29: =IF(G29="","",SUM(K29:O29)) -> 220 | Q29: =IF(P29="","",Q28+P29) -> 5115 | R29: SHADE-A
... G37: 46161 | H37: 20 | J37: 33 | K37: 60 | L37: 40 | M37: 40 | N37: 40 | O37: 40 | P37: =IF(G37="","",SUM(K37:O37)) -> 220 | Q37: =IF(P37="","",Q36+P37) -> 6875 | R37: SHADE-A
G38: 46162 | H38: 18 | J38: 34 | K38: =18*3 -> 54 | L38: 36 | M38: 36 | N38: 36 | O38: 36 | P38: =IF(G38="","",SUM(K38:O38)) -> 198 | Q38: =IF(P38="","",Q37+P38) -> 7073 | R38: SHADE-A
G39: 46162 | H39: 17 | J39: 35 | K39: =17*3 -> 51 | L39: 34 | M39: 34 | N39: 34 | O39: 34 | P39: =IF(G39="","",SUM(K39:O39)) -> 187 | Q39: =IF(P39="","",Q38+P39) -> 7260 | R39: SHADE-A
P40: =IF(G40="","",SUM(K40:O40)) | Q40: =IF(P40="","",Q39+P40)
J41: Total: | K41: =SUM(K5:K40) -> 1980 | L41: =SUM(L5:L40) -> 1320 | M41: =SUM(M5:M40) -> 1320 | N41: =SUM(N5:N40) -> 1320 | O41: =SUM(O5:O40) -> 1320 | P41: =SUM(K41:O41) -> 7260
J42: Excess Cut: | K42: =IF(K3="","",K41-K3) -> 21 | L42: =IF(L3="","",L41-L3) -> 14 | M42: =IF(M3="","",M41-M3) -> 14 | N42: =IF(N3="","",N41-N3) -> 14 | O42: =IF(O3="","",O41-O3) -> 14 | P42: =SUM(K42:O42) -> 77
J43: 32 | K43: =SUM(K5:K36) -> 1815 | L43: =SUM(L5:L36) -> 1210 | M43: =SUM(M5:M36) -> 1210 | N43: =SUM(N5:N36) -> 1210 | O43: =SUM(O5:O36) -> 1210 | P43: =SUM(P5:P36) -> 6655
I44: CUTTING SUMMARY
J45: Size Wise Order Breakdown: | K45: 4242 | L45: 2828 | M45: 2828 | N45: 2828 | O45: 2828 | P45: =SUM(K45:O45) -> 15554
A46: Buyer | B46: Style | C46: P.O No. | D46: Color | E46: P.O Total | F46: Label | G46: Date | H46: Lay Qty | I46: No of Ratio | J46: Cut No. | K46: XS | L46: S | M46: M | N46: L | O46: XL | P46: Total | Q46: Grand Total | R46: REMARKS
A47: GREENSOURCE | B47: SHACKET-G074 | C47: 14222 | D47: HEART PARADE | E47: =P45 -> 15554 | G47: 46162 | H47: 23 | J47: 36 | K47: =23*3 -> 69 | L47: =23*2 -> 46 | M47: =23*2 -> 46 | N47: =23*2 -> 46 | O47: =23*2 -> 46 | P47: =IF(G47="","",SUM(K47:O47)) -> 253 | Q47: =IF(P47="","",P47) -> 253 | R47: SHADE-A,C
...

Sheet WANDER IKAT
I1: SILVER COMPOSITE TEXTILE MILS LIMITETD. (UNIT-01)
I2: CUTTING SUMMARY
J3: Size Wise Order Breakdown: | K3: 1306 | L3: 1306 | M3: 1306 | N3: 1959 | O3: 1306 | P3: =SUM(K3:O3) -> 7183
A4: Buyer | B4: Style | C4: P.O No. | D4: Color | E4: P.O Total | F4: Label | G4: Date | H4: Lay Qty | I4: No of Ratio | J4: Cut No. | K4: XS | L4: S | M4: M | N4: L | O4: XL | P4: Total | Q4: Grand Total | R4: REMARKS
A5: GREENSOURCE | B5: SHACKET-G074 | C5: 14220 | D5: WANDER IKAT | E5: =P3 -> 7183 | G5: 46152 | H5: 19 | J5: 1 | K5: =19*2 -> 38 | L5: =19*2 -> 38 | M5: =19*2 -> 38 | N5: =19*3 -> 57 | O5: =19*2 -> 38 | P5: =IF(G5="","",SUM(K5:O5)) -> 209 | Q5: =IF(P5="","",P5) -> 209 | R5: SHADE-A
A6: FW26 | D6: BLUE | G6: 46153 | H6: 15 | J6: 2 | K6: =15*2 -> 30 | L6: =15*2 -> 30 | M6: =15*2 -> 30 | N6: =15*3 -> 45 | O6: =15*2 -> 30 | P6: =IF(G6="","",SUM(K6:O6)) -> 165 | Q6: =IF(P6="","",Q5+P6) -> 374 | R6: SHADE-A
G7: 46153 | H7: 15 | J7: 3 | K7: =15*2 -> 30 | L7: =15*2 -> 30 | M7: =15*2 -> 30 | N7: =15*3 -> 45 | O7: =15*2 -> 30 | P7: =IF(G7="","",SUM(K7:O7)) -> 165 | Q7: =IF(P7="","",Q6+P7) -> 539 | R7: SHADE-A
G8: 46154 | H8: 17 | J8: 4 | K8: 34 | L8: 34 | M8: 34 | N8: 51 | O8: 34 | P8: =IF(G8="","",SUM(K8:O8)) -> 187 | Q8: =IF(P8="","",Q7+P8) -> 726 | R8: SHADE-A
G9: 46154 | H9: 18 | J9: 5 | K9: 36 | L9: 36 | M9: 36 | N9: 54 | O9: 36 | P9: =IF(G9="","",SUM(K9:O9)) -> 198 | Q9: =IF(P9="","",Q8+P9) -> 924 | R9: SHADE-A
G10: 46155 | H10: 15 | J10: 6 | K10: 30 | L10: 30 | M10: 30 | N10: 45 | O10: 30 | P10: =IF(G10="","",SUM(K10:O10)) -> 165 | Q10: =IF(P10="","",Q9+P10) -> 1089 | R10: SHADE-A
G11: 46155 | H11: 15 | J11: 7 | K11: 30 | L11: 30 | M11: 30 | N11: 45 | O11: 30 | P11: =IF(G11="","",SUM(K11:O11)) -> 165 | Q11: =IF(P11="","",Q10+P11) -> 1254 | R11: SHADE-A
G12: 46155 | H12: 15 | J12: 8 | K12: 30 | L12: 30 | M12: 30 | N12: 45 | O12: 30 | P12: =IF(G12="","",SUM(K12:O12)) -> 165 | Q12: =IF(P12="","",Q11+P12) -> 1419 | R12: SHADE-A
G13: 46155 | H13: 20 | J13: 9 | K13: 40 | L13: 40 | M13: 40 | N13: 60 | O13: 40 | P13: =IF(G13="","",SUM(K13:O13)) -> 220 | Q13: =IF(P13="","",Q12+P13) -> 1639 | R13: SHADE-A
G14: 46155 | H14: 20 | J14: 10 | K14: 40 | L14: 40 | M14: 40 | N14: 60 | O14: 40 | P14: =IF(G14="","",SUM(K14:O14)) -> 220 | Q14: =IF(P14="","",Q13+P14) -> 1859 | R14: SHADE-A
G15: 46156 | H15: 20 | J15: 11 | K15: 40 | L15: 40 | M15: 40 | N15: 60 | O15: 40 | P15: =IF(G15="","",SUM(K15:O15)) -> 220 | Q15: =IF(P15="","",Q14+P15) -> 2079 | R15: SHADE-A
G16: 46156 | H16: 20 | J16: 12 | K16: 40 | L16: 40 | M16: 40 | N16: 60 | O16: 40 | P16: =IF(G16="","",SUM(K16:O16)) -> 220 | Q16: =IF(P16="","",Q15+P16) -> 2299 | R16: SHADE-A
G17: 46156 | H17: 20 | J17: 13 | K17: 40 | L17: 40 | M17: 40 | N17: 60 | O17: 40 | P17: =IF(G17="","",SUM(K17:O17)) -> 220 | Q17: =IF(P17="","",Q16+P17) -> 2519 | R17: SHADE-A
G18: 46156 | H18: 20 | J18: 14 | K18: 40 | L18: 40 | M18: 40 | N18: 60 | O18: 40 | P18: =IF(G18="","",SUM(K18:O18)) -> 220 | Q18: =IF(P18="","",Q17+P18) -> 2739 | R18: SHADE-A
G19: 46158 | H19: 20 | J19: 15 | K19: 40 | L19: 40 | M19: 40 | N19: 60 | O19: 40 | P19: =IF(G19="","",SUM(K19:O19)) -> 220 | Q19: =IF(P19="","",Q18+P19) -> 2959 | R19: SHADE-A
... G21: 46158 | H21: 20 | J21: 17 | K21: 40 | L21: 40 | M21: 40 | N21: 60 | O21: 40 | P21: =IF(G21="","",SUM(K21:O21)) -> 220 | Q21: =IF(P21="","",Q20+P21) -> 3399 | R21: SHADE-A
G22: 46158 | H22: 20 | J22: 18 | K22: =20*2 -> 40 | L22: =20*2 -> 40 | M22: =20*2 -> 40 | N22: 60 | O22: =20*2 -> 40 | P22: =IF(G22="","",SUM(K22:O22)) -> 220 | Q22: =IF(P22="","",Q21+P22) -> 3619 | R22: SHADE-A
G23: 46158 | H23: 20 | J23: 19 | K23: 40 | L23: 40 | M23: 40 | N23: 60 | O23: 40 | P23: =IF(G23="","",SUM(K23:O23)) -> 220 | Q23: =IF(P23="","",Q22+P23) -> 3839 | R23: SHADE-A
G24: 46158 | H24: 20 | J24: 20 | K24: =20*2 -> 40 | L24: =20*2 -> 40 | M24: =20*2 -> 40 | N24: 60 | O24: =20*2 -> 40 | P24: =IF(G24="","",SUM(K24:O24)) -> 220 | Q24: =IF(P24="","",Q23+P24) -> 4059 | R24: SHADE-A
G25: 46159 | H25: 20 | J25: 21 | K25: 40 | L25: 40 | M25: 40 | N25: 60 | O25: 40 | P25: =IF(G25="","",SUM(K25:O25)) -> 220 | Q25: =IF(P25="","",Q24+P25) -> 4279 | R25: SHADE-A
G26: 46159 | H26: 20 | J26: 22 | K26: 40 | L26: 40 | M26: 40 | N26: 60 | O26: 40 | P26: =IF(G26="","",SUM(K26:O26)) -> 220 | Q26: =IF(P26="","",Q25+P26) -> 4499 | R26: SHADE-A
G27: 46159 | H27: 20 | J27: 23 | K27: 40 | L27: 40 | M27: 40 | N27: 60 | O27: 40 | P27: =IF(G27="","",SUM(K27:O27)) -> 220 | Q27: =IF(P27="","",Q26+P27) -> 4719 | R27: SHADE-A
G28: 46159 | H28: 20 | J28: 24 | K28: 40 | L28: 40 | M28: 40 | N28: 60 | O28: 40 | P28: =IF(G28="","",SUM(K28:O28)) -> 220 | Q28: =IF(P28="","",Q27+P28) -> 4939 | R28: SHADE-A
G29: 46159 | H29: 20 | J29: 25 | K29: 40 | L29: 40 | M29: 40 | N29: 60 | O29: 40 | P29: =IF(G29="","",SUM(K29:O29)) -> 220 | Q29: =IF(P29="","",Q28+P29) -> 5159 | R29: SHADE-A
G30: 46159 | H30: 20 | J30: 26 | K30: 40 | L30: 40 | M30: 40 | N30: 60 | O30: 40 | P30: =IF(G30="","",SUM(K30:O30)) -> 220 | Q30: =IF(P30="","",Q29+P30) -> 5379 | R30: SHADE-A
G31: 46160 | H31: 20 | J31: 27 | K31: 40 | L31: 40 | M31: 40 | N31: 60 | O31: 40 | P31: =IF(G31="","",SUM(K31:O31)) -> 220 | Q31: =IF(P31="","",Q30+P31) -> 5599 | R31: SHADE-A
G32: 46160 | H32: 20 | J32: 28 | K32: 40 | L32: 40 | M32: 40 | N32: 60 | O32: 40 | P32: =IF(G32="","",SUM(K32:O32)) -> 220 | Q32: =IF(P32="","",Q31+P32) -> 5819 | R32: SHADE-A
G33: 46160 | H33: 20 | J33: 29 | K33: 40 | L33: 40 | M33: 40 | N33: 60 | O33: 40 | P33: =IF(G33="","",SUM(K33:O33)) -> 220 | Q33: =IF(P33="","",Q32+P33) -> 6039 | R33: SHADE-A
G34: 46160 | H34: 20 | J34: 30 | K34: 40 | L34: 40 | M34: 40 | N34: 60 | O34: 40 | P34: =IF(G34="","",SUM(K34:O34)) -> 220 | Q34: =IF(P34="","",Q33+P34) -> 6259 | R34: SHADE-A
G35: 46160 | H35: 20 | J35: 31 | K35: 40 | L35: 40 | M35: 40 | N35: 60 | O35: 40 | P35: =IF(G35="","",SUM(K35:O35)) -> 220 | Q35: =IF(P35="","",Q34+P35) -> 6479 | R35: SHADE-A
G36: 46160 | H36: 20 | J36: 32 | K36: 40 | L36: 40 | M36: 40 | N36: 60 | O36: 40 | P36: =IF(G36="","",SUM(K36:O36)) -> 220 | Q36: =IF(P36="","",Q35+P36) -> 6699 | R36: SHADE-A
... G38: 46161 | H38: 20 | J38: 34 | K38: 40 | L38: 40 | M38: 40 | N38: 60 | O38: 40 | P38: =IF(G38="","",SUM(K38:O38)) -> 220 | Q38: =IF(P38="","",Q37+P38) -> 7139 | R38: SHADE-A
G39: 46161 | H39: 11 | J39: 35 | K39: 22 | L39: 22 | M39: 22 | N39: =11*3 -> 33 | O39: 22 | P39: =IF(G39="","",SUM(K39:O39)) -> 121 | Q39: =IF(P39="","",Q38+P39) -> 7260 | R39: SHADE-A
P40: =IF(G40="","",SUM(K40:O40)) | Q40: =IF(P40="","",Q39+P40)
J41: Total: | K41: =SUM(K5:K40) -> 1320 | L41: =SUM(L5:L40) -> 1320 | M41: =SUM(M5:M40) -> 1320 | N41: =SUM(N5:N40) -> 1980 | O41: =SUM(O5:O40) -> 1320 | P41: =SUM(K41:O41) -> 7260
J42: Excess Cut: | K42: =IF(K3="","",K41-K3) -> 14 | L42: =IF(L3="","",L41-L3) -> 14 | M42: =IF(M3="","",M41-M3) -> 14 | N42: =IF(N3="","",N41-N3) -> 21 | O42: =IF(O3="","",O41-O3) -> 14 | P42: =SUM(K42:O42) -> 77
...

Sheet WILD ONE
I1: SILVER COMPOSITE TEXTILE MILS LIMITETD. (UNIT-01)
I2: CUTTING SUMMARY
J3: Size Wise Order Breakdown: | K3: 1306 | L3: 1306 | M3: 1959 | N3: 1959 | O3: 1306 | P3: =SUM(K3:O3) -> 7836
A4: Buyer | B4: Style | C4: P.O No. | D4: Color | E4: P.O Total | F4: Label | G4: Date | H4: Lay Qty | I4: No of Ratio | J4: Cut No. | K4: XS | L4: S | M4: M | N4: L | O4: XL | P4: Total | Q4: Grand Total | R4: REMARKS
A5: GREENSOURCE | B5: SHACKET-G074 | C5: 14220 | D5: WILD ONE | E5: =P3 -> 7836 | G5: 46152 | H5: 15 | J5: 1 | K5: 30 | L5: 30 | M5: 45 | N5: 45 | O5: 30 | P5: =IF(G5="","",SUM(K5:O5)) -> 180 | Q5: =IF(P5="","",P5) -> 180 | R5: SHADE-A
A6: FW26 | D6: BROWN | G6: 46153 | H6: 16 | J6: 2 | K6: 32 | L6: 32 | M6: 48 | N6: 48 | O6: 32 | P6: =IF(G6="","",SUM(K6:O6)) -> 192 | Q6: =IF(P6="","",Q5+P6) -> 372 | R6: SHADE-A
G7: 46154 | H7: 18 | J7: 3 | K7: 36 | L7: 36 | M7: =18*3 -> 54 | N7: =18*3 -> 54 | O7: 36 | P7: =IF(G7="","",SUM(K7:O7)) -> 216 | Q7: =IF(P7="","",Q6+P7) -> 588 | R7: SHADE-A
G8: 46154 | H8: 18 | J8: 4 | K8: 36 | L8: 36 | M8: =18*3 -> 54 | N8: =18*3 -> 54 | O8: 36 | P8: =IF(G8="","",SUM(K8:O8)) -> 216 | Q8: =IF(P8="","",Q7+P8) -> 804 | R8: SHADE-A
G9: 46154 | H9: 18 | J9: 5 | K9: 36 | L9: 36 | M9: 54 | N9: 54 | O9: 36 | P9: =IF(G9="","",SUM(K9:O9)) -> 216 | Q9: =IF(P9="","",Q8+P9) -> 1020 | R9: SHADE-A
G10: 46154 | H10: 18 | J10: 6 | K10: 36 | L10: 36 | M10: 54 | N10: 54 | O10: 36 | P10: =IF(G10="","",SUM(K10:O10)) -> 216 | Q10: =IF(P10="","",Q9+P10) -> 1236 | R10: SHADE-A
G11: 46154 | H11: 18 | J11: 7 | K11: 36 | L11: 36 | M11: 54 | N11: 54 | O11: 36 | P11: =IF(G11="","",SUM(K11:O11)) -> 216 | Q11: =IF(P11="","",Q10+P11) -> 1452 | R11: SHADE-A
G12: 46155 | H12: 18 | J12: 8 | K12: 36 | L12: 36 | M12: 54 | N12: 54 | O12: 36 | P12: =IF(G12="","",SUM(K12:O12)) -> 216 | Q12: =IF(P12="","",Q11+P12) -> 1668 | R12: SHADE-A
G13: 46155 | H13: 20 | J13: 9 | K13: =20*2 -> 40 | L13: =20*2 -> 40 | M13: =20*3 -> 60 | N13: =20*3 -> 60 | O13: =20*2 -> 40 | P13: =IF(G13="","",SUM(K13:O13)) -> 240 | Q13: =IF(P13="","",Q12+P13) -> 1908 | R13: SHADE-A
G14: 46156 | H14: 18 | J14: 10 | K14: 36 | L14: 36 | M14: =18*3 -> 54 | N14: =18*3 -> 54 | O14: =18*2 -> 36 | P14: =IF(G14="","",SUM(K14:O14)) -> 216 | Q14: =IF(P14="","",Q13+P14) -> 2124 | R14: SHADE-A
G15: 46156 | H15: 20 | J15: 11 | K15: 40 | L15: 40 | M15: 60 | N15: 60 | O15: 40 | P15: =IF(G15="","",SUM(K15:O15)) -> 240 | Q15: =IF(P15="","",Q14+P15) -> 2364 | R15: SHADE-A
G16: 46156 | H16: 20 | J16: 12 | K16: 40 | L16: 40 | M16: 60 | N16: 60 | O16: 40 | P16: =IF(G16="","",SUM(K16:O16)) -> 240 | Q16: =IF(P16="","",Q15+P16) -> 2604 | R16: SHADE-A
G17: 46156 | H17: 20 | J17: 13 | K17: 40 | L17: 40 | M17: 60 | N17: 60 | O17: 40 | P17: =IF(G17="","",SUM(K17:O17)) -> 240 | Q17: =IF(P17="","",Q16+P17) -> 2844 | R17: SHADE-A
G18: 46156 | H18: 20 | J18: 14 | K18: 40 | L18: 40 | M18: 60 | N18: 60 | O18: 40 | P18: =IF(G18="","",SUM(K18:O18)) -> 240 | Q18: =IF(P18="","",Q17+P18) -> 3084 | R18: SHADE-A
G19: 46156 | H19: 20 | J19: 15 | K19: 40 | L19: 40 | M19: 60 | N19: 60 | O19: 40 | P19: =IF(G19="","",SUM(K19:O19)) -> 240 | Q19: =IF(P19="","",Q18+P19) -> 3324 | R19: SHADE-A
G20: 46158 | H20: 20 | J20: 16 | K20: 40 | L20: 40 | M20: 60 | N20: 60 | O20: 40 | P20: =IF(G20="","",SUM(K20:O20)) -> 240 | Q20: =IF(P20="","",Q19+P20) -> 3564 | R20: SHADE-A
G21: 46158 | H21: 20 | J21: 17 | K21: 40 | L21: 40 | M21: 60 | N21: 60 | O21: 40 | P21: =IF(G21="","",SUM(K21:O21)) -> 240 | Q21: =IF(P21="","",Q20+P21) -> 3804 | R21: SHADE-A
G22: 46158 | H22: 20 | J22: 18 | K22: 40 | L22: 40 | M22: 60 | N22: 60 | O22: 40 | P22: =IF(G22="","",SUM(K22:O22)) -> 240 | Q22: =IF(P22="","",Q21+P22) -> 4044 | R22: SHADE-A
G23: 46158 | H23: 20 | J23: 19 | K23: 40 | L23: 40 | M23: 60 | N23: 60 | O23: 40 | P23: =IF(G23="","",SUM(K23:O23)) -> 240 | Q23: =IF(P23="","",Q22+P23) -> 4284 | R23: SHADE-A
G24: 46159 | H24: 20 | J24: 20 | K24: 40 | L24: 40 | M24: 60 | N24: 60 | O24: 40 | P24: =IF(G24="","",SUM(K24:O24)) -> 240 | Q24: =IF(P24="","",Q23+P24) -> 4524 | R24: SHADE-A
G25: 46159 | H25: 20 | J25: 21 | K25: 40 | L25: 40 | M25: 60 | N25: 60 | O25: 40 | P25: =IF(G25="","",SUM(K25:O25)) -> 240 | Q25: =IF(P25="","",Q24+P25) -> 4764 | R25: SHADE-A
G26: 46159 | H26: 20 | J26: 22 | K26: 40 | L26: 40 | M26: 60 | N26: 60 | O26: 40 | P26: =IF(G26="","",SUM(K26:O26)) -> 240 | Q26: =IF(P26="","",Q25+P26) -> 5004 | R26: SHADE-A
... G38: 46162 | H38: 21 | J38: 34 | K38: 42 | L38: 42 | M38: 63 | N38: 63 | O38: 42 | P38: =IF(G38="","",SUM(K38:O38)) -> 252 | Q38: =IF(P38="","",Q37+P38) -> 7920 | R38: SHADE-A
P39: =IF(G39="","",SUM(K39:O39)) | Q39: =IF(P39="","",Q38+P39)
J40: Total: | K40: =SUM(K5:K39) -> 1320 | L40: =SUM(L5:L39) -> 1320 | M40: =SUM(M5:M39) -> 1980 | N40: =SUM(N5:N39) -> 1980 | O40: =SUM(O5:O39) -> 1320 | P40: =SUM(K40:O40) -> 7920
J41: Excess Cut: | K41: =IF(K3="","",K40-K3) -> 14 | L41: =IF(L3="","",L40-L3) -> 14 | M41: =IF(M3="","",M40-M3) -> 21 | N41: =IF(N3="","",N40-N3) -> 21 | O41: =IF(O3="","",O40-O3) -> 14 | P41: =SUM(K41:O41) -> 84
J42: 28 | K42: =SUM(K5:K32) -> 1074 | L42: =SUM(L5:L32) -> 1074 | M42: =SUM(M5:M32) -> 1611 | N42: =SUM(N5:N32) -> 1611 | O42: =SUM(O5:O32) -> 1074 | P42: =SUM(P5:P32) -> 6444
I43: CUTTING SUMMARY
J44: Size Wise Order Breakdown: | K44: 2828 | L44: 2828 | M44: 4242 | N44: 4242 | O44: 2828 | P44: =SUM(K44:O44) -> 16968
A45: Buyer | B45: Style | C45: P.O No. | D45: Color | E45: P.O Total | F45: Label | G45: Date | H45: Lay Qty | I45: No of Ratio | J45: Cut No. | K45: XS | L45: S | M45: M | N45: L | O45: XL | P45: Total | Q45: Grand Total | R45: REMARKS
A46: GREENSOURCE | B46: SHACKET-G074 | C46: 14222 | D46: WILD ONE | E46: =P44 -> 16968 | G46: 46162 | H46: 22 | J46: 35 | K46: =22*2 -> 44 | L46: =22*2 -> 44 | M46: =22*3 -> 66 | N46: =22*3 -> 66 | O46: =22*2 -> 44 | P46: =IF(G46="","",SUM(K46:O46)) -> 264 | Q46: =IF(P46="","",P46) -> 264 | R46: SHADE-A
A47: FW26 | D47: BROWN | G47: 43971 | H47: 20 | J47: 36 | K47: 40 | L47: 40 | M47: 60 | N47: 60 | O47: 40 | P47: =IF(G47="","",SUM(K47:O47)) -> 240 | Q47: =IF(P47="","",Q46+P47) -> 504 | R47: SHADE-A
G48: 46163 | H48: 20 | J48: 37 | K48: 40 | L48: 40 | M48: 60 | N48: 60 | O48: 40 | P48: =IF(G48="","",SUM(K48:O48)) -> 240 | Q48: =IF(P48="","",Q47+P48) -> 744 | R48: SHADE-A
G49: 46163 | H49: 20 | J49: 38 | K49: 40 | L49: 40 | M49: 60 | N49: 60 | O49: 40 | P49: =IF(G49="","",SUM(K49:O49)) -> 240 | Q49: =IF(P49="","",Q48+P49) -> 984 | R49: SHADE-A
G50: 46163 | H50: 20 | J50: 39 | K50: =20*2 -> 40 | L50: =20*2 -> 40 | M50: 60 | N50: 60 | O50: =20*2 -> 40 | P50: =IF(G50="","",SUM(K50:O50)) -> 240 | Q50: =IF(P50="","",Q49+P50) -> 1224 | R50: SHADE-A
G51: 46165 | H51: 20 | J51: 40 | K51: 40 | L51: 40 | M51: 60 | N51: 60 | O51: 40 | P51: =IF(G51="","",SUM(K51:O51)) -> 240 | Q51: =IF(P51="","",Q50+P51) -> 1464 | R51: SHADE-A
...
